<?xml version="1.0" encoding="utf-8"?>
<!-- =================================================================================== -->
<!-- |    This document was autogenerated by xacro from ./xacro/niryo_ned2_camera.urdf.xacro | -->
<!-- |    EDITING THIS FILE BY HAND IS NOT RECOMMENDED                                 | -->
<!-- =================================================================================== -->
<robot name="niryo_ned2">
  <!-- Enable Gazebo control-->
  <gazebo>
    <plugin filename="libgazebo_ros_control.so" name="gazebo_ros_control">
      <robotSimType>gazebo_ros_control/DefaultRobotHWSim</robotSimType>
    </plugin>
  </gazebo>
  <!-- Properties -->
  <!-- Links -->
  <link name="world"/>
  <link name="base_link">
    <inertial>
      <origin rpy="0 0 0" xyz="-0.008924 0.0001357 0.052392"/>
      <mass value="0.71142"/>
      <inertia ixx="0.0017" ixy="0.0" ixz="0.0" iyy="0.0017" iyz="0.0" izz="0.0032"/>
    </inertial>
    <visual>
      <origin rpy="0 0 0" xyz="0 0 0"/>
      <geometry>
        <mesh filename="package://niryo_robot_description/meshes/ned2/collada/base_link.dae"/>
      </geometry>
    </visual>
    <collision>
      <origin rpy="-1.5707963268 0 0" xyz="0 0 0"/>
      <geometry>
        <mesh filename="package://niryo_robot_description/meshes/ned2/stl/base_link.stl"/>
      </geometry>
    </collision>
  </link>
  <link name="led_ring_link">
    <!--
        <visual>
            <origin xyz="0 0 0"
                    rpy="0 0 0"/>
            <geometry>
                <cylinder length="0.0019" radius="0.0775"/>
            </geometry>
            <material
                    name="">
                <color
                        rgba="1 1 1 0.25"/>
            </material>
        </visual> -->
  </link>
  <link name="shoulder_link">
    <inertial>
      <origin rpy="0 0 0" xyz="-0.031951 0.0080419 0.030675"/>
      <mass value="0.35056"/>
      <inertia ixx="0.00023875" ixy="2.3853E-08" ixz="2.0596E-06" iyy="0.00032638" iyz="-8.9319E-07" izz="0.00030089"/>
    </inertial>
    <visual>
      <origin rpy="0 0 0" xyz="0 0 0"/>
      <geometry>
        <mesh filename="package://niryo_robot_description/meshes/ned2/collada/shoulder_link.dae"/>
      </geometry>
    </visual>
    <collision>
      <origin rpy="0 0 0" xyz="0 0 0"/>
      <geometry>
        <mesh filename="package://niryo_robot_description/meshes/ned2/stl/shoulder_link.stl"/>
      </geometry>
    </collision>
  </link>
  <link name="arm_link">
    <inertial>
      <origin rpy="0 3.14159265359 0" xyz="-0.00096976 0.086432 0.0038832"/>
      <mass value="1.0838"/>
      <inertia ixx="0.008194" ixy="0.00015602" ixz="-3.434E-06" iyy="0.0011945" iyz="-0.00031298" izz="0.007915"/>
    </inertial>
    <visual>
      <origin rpy="0 3.14159265359 0" xyz="0 0 0"/>
      <geometry>
        <mesh filename="package://niryo_robot_description/meshes/ned2/collada/arm_link.dae"/>
      </geometry>
    </visual>
    <collision>
      <origin rpy="0 3.14159265359 0" xyz="0 0 0"/>
      <geometry>
        <mesh filename="package://niryo_robot_description/meshes/ned2/stl/arm_link.stl"/>
      </geometry>
    </collision>
  </link>
  <link name="elbow_link">
    <inertial>
      <origin rpy="0 3.14159265359 0" xyz="-0.019703 0.037336 -1.7431E-09"/>
      <mass value="0.22126"/>
      <inertia ixx="0.00011754" ixy="-1.2314E-05" ixz="-6.2064E-11" iyy="0.00020851" iyz="9.2393E-11" izz="0.00022753"/>
    </inertial>
    <visual>
      <origin rpy="0 3.14159265359 0" xyz="0 0 0"/>
      <geometry>
        <mesh filename="package://niryo_robot_description/meshes/ned2/collada/elbow_link.dae"/>
      </geometry>
    </visual>
    <collision>
      <origin rpy="0 3.14159265359 0" xyz="0 0 0"/>
      <geometry>
        <mesh filename="package://niryo_robot_description/meshes/ned2/stl/elbow_link.stl"/>
      </geometry>
    </collision>
  </link>
  <link name="forearm_link">
    <inertial>
      <origin rpy="0 0 0" xyz="-0.0049532 7.8351E-06 0.08106"/>
      <mass value="0.35686"/>
      <inertia ixx="0.0013664" ixy="-9.6367E-08" ixz="0.00013594" iyy="0.0014781" iyz="-1.4596E-07" izz="0.00023715"/>
    </inertial>
    <visual>
      <origin rpy="0 0 0" xyz="0 0 0"/>
      <geometry>
        <mesh filename="package://niryo_robot_description/meshes/ned2/collada/forearm_link.dae"/>
      </geometry>
    </visual>
    <collision>
      <origin rpy="0 0 0" xyz="0 0 0"/>
      <geometry>
        <mesh filename="package://niryo_robot_description/meshes/ned2/stl/forearm_link.stl"/>
      </geometry>
    </collision>
  </link>
  <!-- add collision for the motor of joint 5
    <link name="joint5_motor">
        <inertial>
            <origin xyz="0 0 0.015" rpy="0 0 0"/>
            <mass value="0.203543862275952"/>
            <inertia ixx="0.0015" ixy="0.0" ixz="0.0" iyy="0.0015" iyz="0.0" izz="0.0015"/>
        </inertial>
        <collision>
            <origin xyz="0 0 0.015" rpy="0 0 0"/>
            <geometry>
                <box size="0.047 0.0285 0.03"/>
            </geometry>
        </collision>
    </link> -->
  <link name="wrist_link">
    <inertial>
      <origin rpy="0 0 0" xyz="-0.019666 0.037312 0.0"/>
      <mass value="0.22126"/>
      <inertia ixx="0.0015" ixy="0.0" ixz="0.0" iyy="0.0015" iyz="0.0" izz="0.0015"/>
    </inertial>
    <visual>
      <origin rpy="0 0 0" xyz="0 0 0"/>
      <geometry>
        <mesh filename="package://niryo_robot_description/meshes/ned2/collada/wrist_link.dae"/>
      </geometry>
    </visual>
    <collision>
      <origin rpy="0 0 0" xyz="0 0 0"/>
      <geometry>
        <mesh filename="package://niryo_robot_description/meshes/ned2/stl/wrist_link.stl"/>
      </geometry>
    </collision>
  </link>
  <link name="hand_link">
    <inertial>
      <origin rpy="0 0 0" xyz="0 0 0.009"/>
      <mass value="0.0070027"/>
      <inertia ixx="0.0015" ixy="0.0" ixz="0.0" iyy="0.0015" iyz="0.0" izz="0.0015"/>
    </inertial>
    <visual>
      <origin rpy="0 0 0" xyz="0 0 0"/>
      <geometry>
        <mesh filename="package://niryo_robot_description/meshes/ned2/collada/hand_link.dae"/>
      </geometry>
    </visual>
    <collision>
      <origin rpy="0 0 0" xyz="0 0 0"/>
      <geometry>
        <mesh filename="package://niryo_robot_description/meshes/ned2/stl/hand_link.stl"/>
      </geometry>
    </collision>
  </link>
  <link name="tool_link">
    </link>
  <!-- Joints -->
  <joint name="joint_world" type="fixed">
    <parent link="world"/>
    <child link="base_link"/>
    <origin rpy="0 0 0" xyz="0 0 0"/>
  </joint>
  <joint name="joint_1" type="revolute">
    <origin rpy="0 0 -1.5707963268" xyz="0 0 0.1013"/>
    <parent link="base_link"/>
    <child link="shoulder_link"/>
    <axis xyz="0 0 1"/>
    <limit effort="10.0" lower="-2.99987191833" upper="2.99987191833" velocity="10.0"/>
  </joint>
  <joint name="joint_2" type="revolute">
    <origin rpy="1.5707963268 0 1.5707963268" xyz="0 0 0.065"/>
    <parent link="shoulder_link"/>
    <child link="arm_link"/>
    <axis xyz="0 0 1"/>
    <limit effort="10.0" lower="-1.83259571459" upper="0.610167106497" velocity="8.0"/>
  </joint>
  <joint name="joint_3" type="revolute">
    <origin rpy="0 0 0" xyz="0.012 0.221 0"/>
    <parent link="arm_link"/>
    <child link="elbow_link"/>
    <axis xyz="0 0 1"/>
    <limit effort="7.0" lower="-1.34006379968" upper="1.57009819509" velocity="8.0"/>
  </joint>
  <joint name="joint_4" type="revolute">
    <origin rpy="0 1.5707963268 0" xyz="0.065 0.0325 0"/>
    <parent link="elbow_link"/>
    <child link="forearm_link"/>
    <axis xyz="0 0 1"/>
    <limit effort="7.0" lower="-2.09003177926" upper="2.09003177926" velocity="2.0"/>
  </joint>
  <joint name="joint_5" type="revolute">
    <origin rpy="3.14159265359 -1.5707963268 3.14159265359" xyz="0 0 0.17"/>
    <parent link="forearm_link"/>
    <child link="wrist_link"/>
    <axis xyz="0 0 1"/>
    <limit effort="6.0" lower="-1.92003671012" upper="1.92282923692" velocity="2.0"/>
  </joint>
  <joint name="joint_6" type="revolute">
    <origin rpy="0 1.5707963268 0" xyz="0.0197 0.00925 0"/>
    <parent link="wrist_link"/>
    <child link="hand_link"/>
    <axis xyz="0 0 1"/>
    <limit effort="5.0" lower="-2.53002928369" upper="2.53002928369" velocity="2.0"/>
  </joint>
  <joint name="hand_tool_joint" type="fixed">
    <parent link="hand_link"/>
    <child link="tool_link"/>
    <origin rpy="-1.5707963268 -1.5707963268 0" xyz="0 0 0.0285"/>
  </joint>
  <!--
    <joint name="joint_test" type="fixed">
        <origin xyz="-0.03 0 0.158" rpy="0 -${PI/2} 0"/>
        <parent link="forearm_link"/>
        <child link="joint5_motor"/>
    </joint> -->
  <joint name="joint_led_ring" type="fixed">
    <parent link="world"/>
    <child link="led_ring_link"/>
    <origin rpy="0 0 0" xyz="0 0 0.0923"/>
  </joint>
  <transmission name="transmission_1">
    <type>transmission_interface/SimpleTransmission</type>
    <joint name="joint_1">
      <hardwareInterface>hardware_interface/PositionJointInterface</hardwareInterface>
    </joint>
    <actuator name="motor_1">
      <mechanicalReduction>1</mechanicalReduction>
    </actuator>
  </transmission>
  <transmission name="transmission_2">
    <type>transmission_interface/SimpleTransmission</type>
    <joint name="joint_2">
      <hardwareInterface>hardware_interface/PositionJointInterface</hardwareInterface>
    </joint>
    <actuator name="motor_2">
      <mechanicalReduction>1</mechanicalReduction>
    </actuator>
  </transmission>
  <transmission name="transmission_3">
    <type>transmission_interface/SimpleTransmission</type>
    <joint name="joint_3">
      <hardwareInterface>hardware_interface/PositionJointInterface</hardwareInterface>
    </joint>
    <actuator name="motor_3">
      <mechanicalReduction>1</mechanicalReduction>
    </actuator>
  </transmission>
  <transmission name="transmission_4">
    <type>transmission_interface/SimpleTransmission</type>
    <joint name="joint_4">
      <hardwareInterface>hardware_interface/PositionJointInterface</hardwareInterface>
    </joint>
    <actuator name="motor_4">
      <mechanicalReduction>1</mechanicalReduction>
    </actuator>
  </transmission>
  <transmission name="transmission_5">
    <type>transmission_interface/SimpleTransmission</type>
    <joint name="joint_5">
      <hardwareInterface>hardware_interface/PositionJointInterface</hardwareInterface>
    </joint>
    <actuator name="motor_5">
      <mechanicalReduction>1</mechanicalReduction>
    </actuator>
  </transmission>
  <transmission name="transmission_6">
    <type>transmission_interface/SimpleTransmission</type>
    <joint name="joint_6">
      <hardwareInterface>hardware_interface/PositionJointInterface</hardwareInterface>
    </joint>
    <actuator name="motor_6">
      <mechanicalReduction>1</mechanicalReduction>
    </actuator>
  </transmission>
  <!-- Joint for camera -->
  <joint name="camera_joint" type="fixed">
    <axis xyz="0 0 1"/>
    <origin rpy="1.5707963268 0 0.174532925199" xyz="0 0.0385 0"/>
    <parent link="wrist_link"/>
    <child link="camera_link"/>
  </joint>
  <!-- Camera link -->
  <link name="camera_link">
    <visual>
      <origin rpy="0 0 0" xyz="0 0 0"/>
      <geometry>
        <box size="0.01 0.037 0.037"/>
      </geometry>
      <material name="DarkGrey"/>
    </visual>
  </link>
  <!-- Add gazebo settings to make the link an camera ! -->
  <gazebo reference="camera_link">
    <material>Gazebo/DarkGrey</material>
    <sensor name="camera_gazebo" type="camera">
      <update_rate>15.0</update_rate>
      <camera name="head">
        <!--69,33 degrees-->
        <horizontal_fov>1.21</horizontal_fov>
        <!--  <aspect_ratio>1.333</aspect_ratio>-->
        <image>
          <width>640</width>
          <height>480</height>
          <format>R8G8B8</format>
        </image>
        <clip>
          <near>0.03</near>
          <far>2</far>
        </clip>
        <distortion>
          <k1>-0.4146402</k1>
          <k2>0.2407384</k2>
          <p1>-0.0</p1>
          <p2>-0.0</p2>
          <k3>-0.1040042</k3>
          <center>0.5 0.5</center>
        </distortion>
      </camera>
      <plugin filename="libgazebo_ros_camera.so" name="camera_controller">
        <alwaysOn>true</alwaysOn>
        <updateRate>0.0</updateRate>
        <cameraName>gazebo_camera</cameraName>
        <imageTopicName>image_raw</imageTopicName>
        <cameraInfoTopicName>camera_info</cameraInfoTopicName>
        <frameName>camera_link</frameName>
      </plugin>
    </sensor>
  </gazebo>
</robot>
